Workbook

Sheet INVERSIONES
B1: Modelo agrosostenible para la producción agrícola con el fin de promover la adaptación ante el cambio climático en el departamento de Bolívar. Cultivo de Yuca y Frijol Caupí
B2: PRESUPUESTO DE INVERSION
B3: CONCEPTOS | C3: UNIDAD | D3: CANTIDAD | E3: COSTO UNITARIO | F3: TOTAL | G3: Programa | H3: SOCIOS
B4: ACTIVO FIJO
B5: Sistema de riego por goteo fotovoltaico | C5: Obra | D5: 1 | E5: 15000000 | F5: =E5*D5 -> 15000000 | G5: =F5 -> 15000000
B6: Electrobomba/motobomba electrica, Potencia: 3 Hp, Voltaje: 110 V | C6: equipo | D6: 1 | E6: 5000000 | F6: =E6*D6 -> 5000000 | G6: =F6 -> 5000000
B7: Sensor | C7: equipo | D7: 1 | E7: 5200000 | F7: =E7*D7 -> 5200000
F8: =E8*D8 -> 0
F9: =E9*D9 -> 0
F10: =E10*D10 -> 0
F11: =E11*D11 -> 0
F12: =E12*D12 -> 0
B14: Subtotal | F14: =SUM(F5:F13) -> 25200000 | G14: =SUM(G5:G13) -> 20000000 | H14: =SUM(H5:H13) -> 0
B16: ACTIVO DIFERIDO
F17: =E17*D17 -> 0 | H17: =F17 -> 0
B18: Subtotal | F18: =SUM(F17) -> 0 | G18: =SUM(G17) -> 0 | H18: =SUM(H17) -> 0
B20: CAPITAL DE TRABAJO
B21: Capital de trabajo mensual | C21: Presupuesto | D21: 1 | E21: ='CAPITAL TRABAJO'!C16*-1 -> 0 | F21: =E21*D21 -> 0 | H21: =F21 -> 0
B22: Costo de produccion en campo | C22: Presupuesto | D22: 1 | E22: =+CULTIVO!E45 -> 7714900 | F22: =E22*D22 -> 7714900 | H22: =F22 -> 7714900
B23: Subtotal | F23: =SUM(F21:F22) -> 7714900 | G23: =SUM(G21:G22) -> 0 | H23: =SUM(H21:H22) -> 7714900
B25: TOTAL | F25: =SUM(F14+F18+F23) -> 32914900 | G25: =SUM(G14+G18+G23) -> 20000000 | H25: =SUM(H14+H18+H23) -> 7714900

Sheet CULTIVO
B2: COSTO DE PRODUCCIÓN DEL CULTIVO
B3: Costo de Produccion para 1 hectarea de cultivo de yuca y frijol caupí
B4: CONCEPTO | C4: COSTO/UN | D4: UNID | E4: SUMA | F4: Costo de Produccion para 20 hectareas
B6: PREPARACIÓN DE SUELOS
B7: Limpieza del terreno y adecuación de linderos | C7: 1350000 | D7: 1 | E7: =+C7*D7 -> 1350000
B8: Mecanización (Arado y rastrillado) | C8: 1580000 | D8: 1 | E8: =C8*D8 -> 1580000
B9: Cerramiento (Postes, alambre..) | C9: 2070000 | D9: 1 | E9: =C9*D9 -> 2070000
B12: Subtotal | E12: =SUM(E7:E11) -> 5000000 | G12: =E12*20 -> 100000000
B14: SIEMBRA
B15: Semilla de yuca | C15: 7000 | D15: 100 | E15: =C15*D15 -> 700000
B16: Siembra de frijol Caupí | C16: 20000 | D16: 4 | E16: =C16*D16 -> 80000
B17: Subtotal | E17: =SUM(E15:E16) -> 780000 | G17: =E17*20 -> 15600000
B19: FERTILIZACIÓN
B20: Fertilizante 17-6-18-2 (Producción), Bulto por 50 Kg. | C20: 200900 | D20: 1 | E20: =C20*D20 -> 200900
B21: Cal liquida (2 litros). | C21: 29000 | D21: 1 | E21: =C21*D21 -> 29000
B22: Agrimin, Fertilizante 8-5-0-6, Bulto por 46 Kg | C22: 210200 | D22: 1 | E22: =C22*D22 -> 210200
B23: Abono orgánico compost, bulto de 40 Kg. | C23: 240000 | D23: 1 | E23: =C23*D23 -> 240000
B24: Aplicación | E24: =C24*D24 -> 0
B25: Subtotal | E25: =SUM(E20:E24) -> 680100 | G25: =E25*20 -> 13602000
B27: CONTROL DE PLAGAS Y ENFERMEDADES
B28: Guadaña75 | C28: 124800 | D28: 1 | E28: =C28*D28 -> 124800
B29: miterra (insecticida) | C29: 130000 | D29: 1 | E29: =C29*D29 -> 130000
B30: Coloso | E30: =C30*D30 -> 0
B31: Cruiser TS (trat semilla) | E31: =C31*D31 -> 0
B32: Finale | E32: =C32*D32 -> 0
B33: Tordon | E33: =C33*D33 -> 0
B34: Aplicación | E34: =C34*D34 -> 0
B35: Subtotal | E35: =SUM(E28:E34) -> 254800 | G35: =E35*20 -> 5096000
B37: RIEGO | E37: =D37*C37 -> 0 | G37: =E37*20 -> 0
B39: COSECHA
B40: Corte | C40: 4000 | D40: 250 | E40: =C40*D40 -> 1000000
E41: =C41*D41 -> 0
B42: Subtotal | E42: =SUM(E40:E41) -> 1000000 | G42: =E42*20 -> 20000000
D45: SUMA $ | E45: =SUM(E12+E17+E25+E35+E37+E42) -> 7714900 | G45: =SUM(G6:G43) -> 154298000
B48: CULTIVO: | D48: Yuca + Frijol Caupí
B49: SUPERFICIE (HA) | D49: 1
B50: RENDIMIENTO YUCA (TON/HA): | D50: 12
B51: RENDIMIENTO FRIJOL (TON/HA): | D51: 0.5
B52: PRODUCCION TOTAL (kg) | D52: =(D50+D51)*D49*1000 -> 12500
B53: PRODUCCION DE YUCA BULTOS DE 50 KG | D53: =+((D50*1000)/50)*D49 -> 240
...

Sheet ACOPIO
C2: =INVERSIONES!B1 -> Modelo agrosostenible para la producción agrícola con el fin de promover la adaptación ante el cambio climático en el departamento de Bolívar. Cultivo de Yuca y Frijol Caupí
B3: Capacidad de Acopio de la yuca y frijol
B5: Concepto/Mes | C5: Ene | D5: Feb | E5: Mar | F5: Abr | G5: May | H5: Jun | I5: Jul | J5: Ago | K5: Sep | L5: Oct | M5: Nov | N5: Dic | O5: Total | P5: Año 2 | Q5: Año 3 | R5: Año 4 | S5: Año 5
B6: Compra (Ton):
B7: Yuca | C7: 0 | D7: 0 | E7: 0 | F7: 0 | G7: 0 | H7: 0 | I7: 0 | J7: 0 | K7: 0 | L7: 0 | M7: 0 | N7: 0 | O7: =SUM(C7:N7) -> 0 | P7: =O7*1.05 -> 0 | Q7: =P7*1.05 -> 0 | R7: =Q7*1.05 -> 0 | S7: =R7*1.05 -> 0
B8: Frijol Caupí | C8: 0 | D8: 0 | E8: 0 | F8: 0 | G8: 0 | H8: 0 | I8: 0 | J8: 0 | K8: 0 | L8: 0 | M8: 0 | N8: 0 | O8: =SUM(C8:N8) -> 0 | P8: =O8*1.05 -> 0 | Q8: =P8*1.05 -> 0 | R8: =Q8*1.05 -> 0 | S8: =R8*1.05 -> 0
B10: Total | C10: =SUM(C7:C9) -> 0 | D10: =SUM(D7:D9) -> 0 | E10: =SUM(E7:E9) -> 0 | F10: =SUM(F7:F9) -> 0 | G10: =SUM(G7:G9) -> 0 | H10: =SUM(H7:H9) -> 0 | I10: =SUM(I7:I9) -> 0 | J10: =SUM(J7:J9) -> 0 | ... N10: =SUM(N7:N9) -> 0 | O10: =SUM(C10:N10) -> 0
B12: Precio de compra: ($/ton)
B13: =B7 -> Yuca | C13: 0 | D13: =C13 -> 0 | E13: =D13 -> 0 | F13: =E13 -> 0 | G13: =F13 -> 0 | H13: =G13 -> 0 | I13: =H13 -> 0 | J13: =I13 -> 0 | K13: =J13 -> 0 | ... N13: =M13 -> 0
B14: =+B8 -> Frijol Caupí | C14: 0 | D14: =C14 -> 0 | E14: =D14 -> 0 | F14: =E14 -> 0 | G14: =F14 -> 0 | H14: =G14 -> 0 | I14: =H14 -> 0 | J14: =I14 -> 0 | K14: =J14 -> 0 | ... N14: =M14 -> 0
B16: Costo de acopiado | C16: =SUM(C17:C19) -> 0 | D16: =SUM(D17:D19) -> 0 | E16: =SUM(E17:E19) -> 0 | F16: =SUM(F17:F19) -> 0 | G16: =SUM(G17:G19) -> 0 | H16: =SUM(H17:H19) -> 0 | I16: =SUM(I17:I19) -> 0 | J16: =SUM(J17:J19) -> 0 | ... O16: =SUM(O17:O19) -> 0
B17: =B13 -> Yuca | C17: =C13*C7 -> 0 | D17: =D13*D7 -> 0 | E17: =E13*E7 -> 0 | F17: =F13*F7 -> 0 | G17: =G13*G7 -> 0 | H17: =H13*H7 -> 0 | I17: =I13*I7 -> 0 | J17: =J13*J7 -> 0 | ... N17: =N13*N7 -> 0 | O17: =SUM(C17:N17) -> 0
B18: =+B8 -> Frijol Caupí | C18: =C14*C8 -> 0 | D18: =D14*D8 -> 0 | E18: =E14*E8 -> 0 | F18: =F14*F8 -> 0 | G18: =G14*G8 -> 0 | H18: =H14*H8 -> 0 | I18: =I14*I8 -> 0 | J18: =J14*J8 -> 0 | ... N18: =N14*N8 -> 0 | O18: =SUM(C18:N18) -> 0
B20: Mermas (5%) (ton)
B21: =B13 -> Yuca | C21: =C7*5% -> 0 | D21: =D7*5% -> 0 | E21: =E7*5% -> 0 | F21: =F7*5% -> 0 | G21: =G7*5% -> 0 | H21: =H7*5% -> 0 | I21: =I7*5% -> 0 | J21: =J7*5% -> 0 | ... N21: =N7*5% -> 0
B22: =+B18 -> Frijol Caupí | C22: =C8*5% -> 0 | D22: =D8*5% -> 0 | E22: =E8*5% -> 0 | F22: =F8*5% -> 0 | G22: =G8*5% -> 0 | H22: =H8*5% -> 0 | I22: =I8*5% -> 0 | J22: =J8*5% -> 0 | ... N22: =N8*5% -> 0
B24: Volumen Neta para venta (ton) | C24: =SUM(C25:C27) -> 0 | D24: =SUM(D25:D27) -> 0 | E24: =SUM(E25:E27) -> 0 | F24: =SUM(F25:F27) -> 0 | G24: =SUM(G25:G27) -> 0 | H24: =SUM(H25:H27) -> 0 | I24: =SUM(I25:I27) -> 0 | J24: =SUM(J25:J27) -> 0 | ... N24: =SUM(N25:N27) -> 0
B25: =B21 -> Yuca | C25: =C7-C21 -> 0 | D25: =D7-D21 -> 0 | E25: =E7-E21 -> 0 | F25: =F7-F21 -> 0 | G25: =G7-G21 -> 0 | H25: =H7-H21 -> 0 | I25: =I7-I21 -> 0 | J25: =J7-J21 -> 0 | ... N25: =N7-N21 -> 0 | O25: =SUM(C25:N25) -> 0
B26: =+B22 -> Frijol Caupí | C26: =C8-C22 -> 0 | D26: =D8-D22 -> 0 | E26: =E8-E22 -> 0 | F26: =F8-F22 -> 0 | G26: =G8-G22 -> 0 | H26: =H8-H22 -> 0 | I26: =I8-I22 -> 0 | J26: =J8-J22 -> 0 | ... N26: =N8-N22 -> 0 | O26: =SUM(C26:N26) -> 0
B28: Volmente Neto para Venta (Kg)
B29: =B25 -> Yuca | C29: =C25*1000 -> 0 | D29: =D25*1000 -> 0 | E29: =E25*1000 -> 0 | F29: =F25*1000 -> 0 | G29: =G25*1000 -> 0 | H29: =H25*1000 -> 0 | I29: =I25*1000 -> 0 | J29: =J25*1000 -> 0 | ... O29: =O25*1000 -> 0
B30: =+B26 -> Frijol Caupí | C30: =C26*1000 -> 0 | D30: =D26*1000 -> 0 | E30: =E26*1000 -> 0 | F30: =F26*1000 -> 0 | G30: =G26*1000 -> 0 | H30: =H26*1000 -> 0 | I30: =I26*1000 -> 0 | J30: =J26*1000 -> 0 | ... O30: =O26*1000 -> 0

Sheet MEMORIA COSTOS
B1: =ACOPIO!C2 -> Modelo agrosostenible para la producción agrícola con el fin de promover la adaptación ante el cambio climático en el departamento de Bolívar. Cultivo de Yuca y Frijol Caupí
C2: P r o y e c c i o n M e n s u a l d e C o s t o s
B4: Concepto/Mes | C4: Mes 1 | D4: Mes 2 | E4: Mes 3 | F4: Mes 4 | G4: Mes 5 | H4: Mes 6 | I4: Mes 7 | J4: Mes 8 | K4: Mes 9 | L4: Mes 10 | M4: Mes 11 | N4: Mes 12 | O4: Total
B5: Costos Fijos
B6: =B54 -> Mano de obra para acopio | G6: =+G54 -> 0 | O6: =SUM(C6:N6) -> 0
B7: =B55 -> Mano de obra para carga y descarga | G7: =+G55 -> 128000 | O7: =SUM(C7:N7) -> 128000
B8: =B56 -> Administrador general | C8: =G56 -> 0 | D8: =C8 -> 0 | E8: =D8 -> 0 | F8: =E8 -> 0 | G8: =+G56 -> 0 | H8: =G8 -> 0 | I8: =H8 -> 0 | J8: =I8 -> 0 | K8: =J8 -> 0 | L8: =K8 -> 0 | M8: =L8 -> 0 | N8: =M8 -> 0 | O8: =SUM(C8:N8) -> 0
B9: =B57 -> Contabilidad | C9: =G57 -> 0 | D9: =C9 -> 0 | E9: =D9 -> 0 | F9: =E9 -> 0 | G9: =+G57 -> 0 | H9: =G9 -> 0 | I9: =H9 -> 0 | J9: =I9 -> 0 | K9: =J9 -> 0 | L9: =K9 -> 0 | M9: =L9 -> 0 | N9: =M9 -> 0 | O9: =SUM(C9:N9) -> 0
B10: =B58 -> Pago de luz | C10: =G58 -> 0 | D10: =C10 -> 0 | E10: =D10 -> 0 | F10: =E10 -> 0 | G10: =+G58 -> 0 | H10: =G10 -> 0 | I10: =H10 -> 0 | J10: =I10 -> 0 | K10: =J10 -> 0 | L10: =K10 -> 0 | M10: =L10 -> 0 | N10: =M10 -> 0 | O10: =SUM(C10:N10) -> 0
B11: =B59 -> Pago de agua | C11: =G59 -> 0 | D11: =C11 -> 0 | E11: =D11 -> 0 | F11: =E11 -> 0 | G11: =+G59 -> 0 | H11: =G11 -> 0 | I11: =H11 -> 0 | J11: =I11 -> 0 | K11: =J11 -> 0 | L11: =K11 -> 0 | M11: =L11 -> 0 | N11: =M11 -> 0 | O11: =SUM(C11:N11) -> 0
B12: =B60 -> Mantenimiento de equipo | G12: =+G60 -> 1000000 | O12: =SUM(C12:N12) -> 1000000
B13: =B61 -> Telefono | C13: =G61 -> 0 | D13: =C13 -> 0 | E13: =D13 -> 0 | F13: =E13 -> 0 | G13: =+G61 -> 0 | H13: =G13 -> 0 | I13: =H13 -> 0 | J13: =I13 -> 0 | K13: =J13 -> 0 | L13: =K13 -> 0 | M13: =L13 -> 0 | N13: =M13 -> 0 | O13: =SUM(C13:N13) -> 0
B14: =B62 -> Ventas | C14: =G62 -> 0 | D14: =C14 -> 0 | E14: =D14 -> 0 | F14: =E14 -> 0 | G14: =+G62 -> 0 | H14: =G14 -> 0 | I14: =H14 -> 0 | J14: =I14 -> 0 | K14: =J14 -> 0 | L14: =K14 -> 0 | M14: =L14 -> 0 | N14: =M14 -> 0 | O14: =SUM(C14:N14) -> 0
G15: =+G63 -> 0
B16: Subtotal | C16: =SUM(C6:C15) -> 0 | D16: =SUM(D6:D15) -> 0 | E16: =SUM(E6:E15) -> 0 | F16: =SUM(F6:F15) -> 0 | G16: =SUM(G6:G15) -> 1128000 | H16: =SUM(H6:H15) -> 0 | I16: =SUM(I6:I15) -> 0 | J16: =SUM(J6:J15) -> 0 | ... N16: =SUM(N6:N15) -> 0 | O16: =SUM(C16:N16) -> 1128000
B17: Costos Variables
B18: Compra de yuca | C18: =ACOPIO!C16 -> 0 | D18: =ACOPIO!D16 -> 0 | E18: =ACOPIO!E16 -> 0 | F18: =ACOPIO!F16 -> 0 | G18: =ACOPIO!G16 -> 0 | H18: =ACOPIO!H16 -> 0 | I18: =ACOPIO!I16 -> 0 | J18: =ACOPIO!J16 -> 0 | ... N18: =ACOPIO!N16 -> 0 | O18: =SUM(C18:N18) -> 0
B19: Fletes | G19: 800000 | O19: =SUM(C19:N19) -> 800000
B20: Bolsas de 50 kg | C20: =((ACOPIO!C24*1000)/50)*0.9 -> 0 | D20: =((ACOPIO!D24*1000)/50)*0.9 -> 0 | E20: =((ACOPIO!E24*1000)/50)*0.9 -> 0 | F20: =((ACOPIO!F24*1000)/50)*0.9 -> 0 | G20: =CULTIVO!D55*1000 -> 250000 | H20: =((ACOPIO!H24*1000)/50)*0.9 -> 0 | I20: =((ACOPIO!I24*1000)/50)*0.9 -> 0 | J20: =((ACOPIO!J24*1000)/50)*0.9 -> 0 | K20: =((ACOPIO!K24*1000)/50)*0.9 -> 0 | L20: =((ACOPIO!L24*1000)/50)*0.9 -> 0 | M20: =((ACOPIO!M24*1000)/50)*0.9 -> 0 | N20: =((ACOPIO!N24*1000)/50)*0.9 -> 0 | O20: =SUM(C20:N20) -> 250000
B22: Subtotal | C22: =SUM(C18:C21) -> 0 | D22: =SUM(D18:D21) -> 0 | E22: =SUM(E18:E21) -> 0 | F22: =SUM(F18:F21) -> 0 | G22: =SUM(G18:G21) -> 1050000 | H22: =SUM(H18:H21) -> 0 | I22: =SUM(I18:I21) -> 0 | J22: =SUM(J18:J21) -> 0 | ... N22: =SUM(N18:N21) -> 0 | O22: =SUM(C22:N22) -> 1050000
B23: Costos Totales | C23: =SUM(C22+C16) -> 0 | D23: =SUM(D22+D16) -> 0 | E23: =SUM(E22+E16) -> 0 | F23: =SUM(F22+F16) -> 0 | G23: =SUM(G22+G16) -> 2178000 | H23: =SUM(H22+H16) -> 0 | I23: =SUM(I22+I16) -> 0 | J23: =SUM(J22+J16) -> 0 | ... N23: =SUM(N22+N16) -> 0 | O23: =SUM(C23:N23) -> 2178000
C25: P r o y e c c i o n A n u a l d e C o s t o s
B26: Conceptos/Año | C26: Año 1 | D26: Año 2 | E26: Año 3 | F26: Año 4 | G26: Año 5
B27: =B5 -> Costos Fijos
B28: =B6 -> Mano de obra para acopio | C28: =O6 -> 0 | D28: =C28*1.05 -> 0 | E28: =D28*1.05 -> 0 | F28: =E28*1.05 -> 0 | G28: =F28*1.05 -> 0
B29: =B7 -> Mano de obra para carga y descarga | C29: =O7 -> 128000 | D29: =C29*1.05 -> 134400 | E29: =D29*1.05 -> 141120 | F29: =E29*1.05 -> 148176 | G29: =F29*1.05 -> 155584.8
B30: =B8 -> Administrador general | C30: =O8 -> 0 | D30: =C30*1.05 -> 0 | E30: =D30*1.05 -> 0 | F30: =E30*1.05 -> 0 | G30: =F30*1.05 -> 0
B31: =B9 -> Contabilidad | C31: =O9 -> 0 | D31: =C31*1.05 -> 0 | E31: =D31*1.05 -> 0 | F31: =E31*1.05 -> 0 | G31: =F31*1.05 -> 0
B32: =B10 -> Pago de luz | C32: =O10 -> 0 | D32: =C32*1.05 -> 0 | E32: =D32*1.05 -> 0 | F32: =E32*1.05 -> 0 | G32: =F32*1.05 -> 0
B33: =B11 -> Pago de agua | C33: =O11 -> 0 | D33: =C33*1.05 -> 0 | E33: =D33*1.05 -> 0 | F33: =E33*1.05 -> 0 | G33: =F33*1.05 -> 0
B34: =B12 -> Mantenimiento de equipo | C34: =O12 -> 1000000 | D34: =C34*1.05 -> 1050000 | E34: =D34*1.05 -> 1102500 | F34: =E34*1.05 -> 1157625 | G34: =F34*1.05 -> 1215506.2
B35: =B13 -> Telefono | C35: =O13 -> 0 | D35: =C35*1.05 -> 0 | E35: =D35*1.05 -> 0 | F35: =E35*1.05 -> 0 | G35: =F35*1.05 -> 0
B36: =B14 -> Ventas | C36: =O14 -> 0 | D36: =C36*1.05 -> 0 | E36: =D36*1.05 -> 0 | F36: =E36*1.05 -> 0 | G36: =F36*1.05 -> 0
B38: =B16 -> Subtotal | C38: =SUM(C28:C37) -> 1128000 | D38: =SUM(D28:D37) -> 1184400 | E38: =SUM(E28:E37) -> 1243620 | F38: =SUM(F28:F37) -> 1305801 | G38: =SUM(G28:G37) -> 1371091.1
B40: =B17 -> Costos Variables
B41: =B18 -> Compra de yuca | C41: =O18 -> 0 | D41: =C41*1.05 -> 0 | E41: =D41*1.05 -> 0 | F41: =E41*1.05 -> 0 | G41: =F41*1.05 -> 0
B42: Produccion de yuca y Frijol Caupí | C42: =+CULTIVO!E45 -> 7714900 | D42: =C42*1.05 -> 8100645 | E42: =D42*1.05 -> 8505677.2 | F42: =E42*1.05 -> 8930961.1 | G42: =F42*1.05 -> 9377509.2
B43: =B19 -> Fletes | C43: =O19 -> 800000 | D43: =C43*1.05 -> 840000 | E43: =D43*1.05 -> 882000 | F43: =E43*1.05 -> 926100 | G43: =F43*1.05 -> 972405
B44: =B20 -> Bolsas de 50 kg | C44: =O20 -> 250000 | D44: =C44*1.05 -> 262500 | E44: =D44*1.05 -> 275625 | F44: =E44*1.05 -> 289406.25 | G44: =F44*1.05 -> 303876.56
B46: =B22 -> Subtotal | C46: =SUM(C41:C45) -> 8764900 | D46: =SUM(D41:D45) -> 9203145 | E46: =SUM(E41:E45) -> 9663302.2 | F46: =SUM(F41:F45) -> 10146467 | G46: =SUM(G41:G45) -> 10653791
...

Sheet COSTOS TOTALES
B1: ='MEMORIA COSTOS'!B1 -> Modelo agrosostenible para la producción agrícola con el fin de promover la adaptación ante el cambio climático en el departamento de Bolívar. Cultivo de Yuca y Frijol Caupí
A2: COSTOS TOTALES
B3: COSTOS FIJOS | C3: AÑO 1 | D3: AÑO 2 | E3: AÑO 3 | F3: AÑO 4 | G3: AÑO 5
B4: ='MEMORIA COSTOS'!B28 -> Mano de obra para acopio | C4: ='MEMORIA COSTOS'!C28 -> 0 | D4: ='MEMORIA COSTOS'!D28 -> 0 | E4: ='MEMORIA COSTOS'!E28 -> 0 | F4: ='MEMORIA COSTOS'!F28 -> 0 | G4: ='MEMORIA COSTOS'!G28 -> 0
B5: ='MEMORIA COSTOS'!B29 -> Mano de obra para carga y descarga | C5: ='MEMORIA COSTOS'!C29 -> 128000 | D5: ='MEMORIA COSTOS'!D29 -> 134400 | E5: ='MEMORIA COSTOS'!E29 -> 141120 | F5: ='MEMORIA COSTOS'!F29 -> 148176 | G5: ='MEMORIA COSTOS'!G29 -> 155584.8
B6: ='MEMORIA COSTOS'!B30 -> Administrador general | C6: ='MEMORIA COSTOS'!C30 -> 0 | D6: ='MEMORIA COSTOS'!D30 -> 0 | E6: ='MEMORIA COSTOS'!E30 -> 0 | F6: ='MEMORIA COSTOS'!F30 -> 0 | G6: ='MEMORIA COSTOS'!G30 -> 0
B7: ='MEMORIA COSTOS'!B31 -> Contabilidad | C7: ='MEMORIA COSTOS'!C31 -> 0 | D7: ='MEMORIA COSTOS'!D31 -> 0 | E7: ='MEMORIA COSTOS'!E31 -> 0 | F7: ='MEMORIA COSTOS'!F31 -> 0 | G7: ='MEMORIA COSTOS'!G31 -> 0
B8: ='MEMORIA COSTOS'!B32 -> Pago de luz | C8: ='MEMORIA COSTOS'!C32 -> 0 | D8: ='MEMORIA COSTOS'!D32 -> 0 | E8: ='MEMORIA COSTOS'!E32 -> 0 | F8: ='MEMORIA COSTOS'!F32 -> 0 | G8: ='MEMORIA COSTOS'!G32 -> 0
B9: ='MEMORIA COSTOS'!B33 -> Pago de agua | C9: ='MEMORIA COSTOS'!C33 -> 0 | D9: ='MEMORIA COSTOS'!D33 -> 0 | E9: ='MEMORIA COSTOS'!E33 -> 0 | F9: ='MEMORIA COSTOS'!F33 -> 0 | G9: ='MEMORIA COSTOS'!G33 -> 0
B10: ='MEMORIA COSTOS'!B34 -> Mantenimiento de equipo | C10: ='MEMORIA COSTOS'!C34 -> 1000000 | D10: ='MEMORIA COSTOS'!D34 -> 1050000 | E10: ='MEMORIA COSTOS'!E34 -> 1102500 | F10: ='MEMORIA COSTOS'!F34 -> 1157625 | G10: ='MEMORIA COSTOS'!G34 -> 1215506.2
B11: ='MEMORIA COSTOS'!B35 -> Telefono | C11: ='MEMORIA COSTOS'!C35 -> 0 | D11: ='MEMORIA COSTOS'!D35 -> 0 | E11: ='MEMORIA COSTOS'!E35 -> 0 | F11: ='MEMORIA COSTOS'!F35 -> 0 | G11: ='MEMORIA COSTOS'!G35 -> 0
B12: ='MEMORIA COSTOS'!B36 -> Ventas | C12: ='MEMORIA COSTOS'!C36 -> 0 | D12: ='MEMORIA COSTOS'!D36 -> 0 | E12: ='MEMORIA COSTOS'!E36 -> 0 | F12: ='MEMORIA COSTOS'!F36 -> 0 | G12: ='MEMORIA COSTOS'!G36 -> 0
B14: TOTAL | C14: =SUM(C4:C13) -> 1128000 | D14: =SUM(D4:D13) -> 1184400 | E14: =SUM(E4:E13) -> 1243620 | F14: =SUM(F4:F13) -> 1305801 | G14: =SUM(G4:G13) -> 1371091.1
B16: COSTOS VARIABLES | C16: AÑO 1 | D16: AÑO 2 | E16: AÑO 3 | F16: AÑO 4 | G16: AÑO 5
B17: ='MEMORIA COSTOS'!B41 -> Compra de yuca | C17: ='MEMORIA COSTOS'!C41 -> 0 | D17: ='MEMORIA COSTOS'!D41 -> 0 | E17: ='MEMORIA COSTOS'!E41 -> 0 | F17: ='MEMORIA COSTOS'!F41 -> 0 | G17: ='MEMORIA COSTOS'!G41 -> 0
B18: ='MEMORIA COSTOS'!B42 -> Produccion de yuca y Frijol Caupí | C18: ='MEMORIA COSTOS'!C42 -> 7714900 | D18: ='MEMORIA COSTOS'!D42 -> 8100645 | E18: ='MEMORIA COSTOS'!E42 -> 8505677.2 | F18: ='MEMORIA COSTOS'!F42 -> 8930961.1 | G18: ='MEMORIA COSTOS'!G42 -> 9377509.2
B19: ='MEMORIA COSTOS'!B43 -> Fletes | C19: ='MEMORIA COSTOS'!C43 -> 800000 | D19: ='MEMORIA COSTOS'!D43 -> 840000 | E19: ='MEMORIA COSTOS'!E43 -> 882000 | F19: ='MEMORIA COSTOS'!F43 -> 926100 | G19: ='MEMORIA COSTOS'!G43 -> 972405
B20: ='MEMORIA COSTOS'!B44 -> Bolsas de 50 kg | C20: ='MEMORIA COSTOS'!C44 -> 250000 | D20: ='MEMORIA COSTOS'!D44 -> 262500 | E20: ='MEMORIA COSTOS'!E44 -> 275625 | F20: ='MEMORIA COSTOS'!F44 -> 289406.25 | G20: ='MEMORIA COSTOS'!G44 -> 303876.56
B23: TOTAL | C23: =SUM(C17:C22) -> 8764900 | D23: =SUM(D17:D22) -> 9203145 | E23: =SUM(E17:E22) -> 9663302.2 | F23: =SUM(F17:F22) -> 10146467 | G23: =SUM(G17:G22) -> 10653791
C25: AÑO 1 | D25: AÑO 2 | E25: AÑO 3 | F25: AÑO 4 | G25: AÑO 5
B26: COSTOS FIJOS | C26: =SUM(C14) -> 1128000 | D26: =SUM(D14) -> 1184400 | E26: =SUM(E14) -> 1243620 | F26: =SUM(F14) -> 1305801 | G26: =SUM(G14) -> 1371091.1
B27: COSTOS VARIABLES | C27: =C23 -> 8764900 | D27: =D23 -> 9203145 | E27: =E23 -> 9663302.2 | F27: =F23 -> 10146467 | G27: =G23 -> 10653791
B28: COSTOS TOTALES | C28: =SUM(C26:C27) -> 9892900 | D28: =SUM(D26:D27) -> 10387545 | E28: =SUM(E26:E27) -> 10906922 | F28: =SUM(F26:F27) -> 11452268 | G28: =SUM(G26:G27) -> 12024882

Sheet INGRESOS
C2: P r o y e c c i o n A n u a l d e I n g r e s o s
C4: Unidades de venta por presentacion
B5: Presentacion/Año | C5: Año 1 | D5: Año 2 | E5: Año 3 | F5: Año 4 | G5: Año 5
B7: Venta de Yuca | C7: =O31 -> 19000000 | D7: =C7*1.05 -> 19950000 | E7: =D7*1.05 -> 20947500 | F7: =E7*1.05 -> 21994875 | G7: =F7*1.05 -> 23094619
B8: Venta de Frijol Caupí
B11: Ingresos Totales | C11: =SUM(C7:C9) -> 19000000 | D11: =SUM(D7:D9) -> 19950000 | E11: =SUM(E7:E9) -> 20947500 | F11: =SUM(F7:F9) -> 21994875 | G11: =SUM(G7:G9) -> 23094619
B13: Programa de Ventas Mensuales de Ajonjoli
B15: Concepto/Mes | C15: Ene | D15: Feb | E15: Mar | F15: Abr | G15: May | H15: Jun | I15: Jul | J15: Ago | K15: Sep | L15: Oct | M15: Nov | N15: Dic | O15: Total Año 1 | P15: Año 2 | Q15: Año 3 | R15: Año 4 | S15: Año 5
B16: Presentaciones
B17: Yuca 50 kg | G17: =+CULTIVO!D53 -> 240 | O17: =SUM(C17:N17) -> 240 | P17: =O17*1.05 -> 252 | Q17: =P17*1.05 -> 264.6 | R17: =Q17*1.05 -> 277.83 | S17: =R17*1.05 -> 291.7215
B18: Frijol Caupí 50 kg | D18: =+CULTIVO!D54 -> 10 | O18: =SUM(C18:N18) -> 10 | P18: =O18*1.05 -> 10.5 | Q18: =P18*1.05 -> 11.025 | R18: =Q18*1.05 -> 11.57625 | S18: =R18*1.05 -> 12.155063
B21: Precio ($/costal)
B22: =B17 -> Yuca 50 kg | C22: 75000 | D22: =C22 -> 75000 | E22: =D22 -> 75000 | F22: =E22 -> 75000 | G22: =F22 -> 75000 | H22: =G22 -> 75000 | I22: =H22 -> 75000 | J22: =I22 -> 75000 | K22: =J22 -> 75000 | ... N22: =M22 -> 75000
B23: =+B18 -> Frijol Caupí 50 kg | C23: 100000 | D23: 100000 | E23: 100000 | F23: 100000 | G23: 100000 | H23: 100000 | I23: 100000 | J23: 100000 | K23: 100000 | L23: 100000 | M23: 100000 | N23: 100000
B26: Ingresos
B27: =B22 -> Yuca 50 kg | C27: =C22*C17 -> 0 | D27: =D22*D17 -> 0 | E27: =E22*E17 -> 0 | F27: =F22*F17 -> 0 | G27: =G22*G17 -> 18000000 | H27: =H22*H17 -> 0 | I27: =I22*I17 -> 0 | J27: =J22*J17 -> 0 | ... N27: =N22*N17 -> 0 | O27: =SUM(C27:N27) -> 18000000
B28: =+B23 -> Frijol Caupí 50 kg | C28: =C23*C18 -> 0 | D28: =D23*D18 -> 1000000 | E28: =E23*E18 -> 0 | F28: =F23*F18 -> 0 | G28: =G23*G18 -> 0 | H28: =H23*H18 -> 0 | I28: =I23*I18 -> 0 | J28: =J23*J18 -> 0 | ... N28: =N23*N18 -> 0 | O28: =SUM(C28:N28) -> 1000000
B31: Ingresos por venta de Yuca + Frijol Caupí | C31: =SUM(C27:C29) -> 0 | D31: =SUM(D27:D29) -> 1000000 | E31: =SUM(E27:E29) -> 0 | F31: =SUM(F27:F29) -> 0 | G31: =SUM(G27:G29) -> 18000000 | H31: =SUM(H27:H29) -> 0 | I31: =SUM(I27:I29) -> 0 | J31: =SUM(J27:J29) -> 0 | ... N31: =SUM(N27:N29) -> 0 | O31: =SUM(C31:N31) -> 19000000

Sheet ESTADO RESULTADOS
B1: ='COSTOS TOTALES'!B1:G1 -> Modelo agrosostenible para la producción agrícola con el fin de promover la adaptación ante el cambio climático en el departamento de Bolívar. Cultivo de Yuca y Frijol Caupí
B2: ESTADO DE RESULTADOS CONSOLIDADO PROYECTADO
B3: ( PESOS )
B4: CONCEPTO/PERIODO | C4: P r o y e c t a d o s
C5: Año 1 | D5: Año 2 | E5: Año 3 | F5: Año 4 | G5: Año 5
B7: INGRESOS POR VENTAS | C7: =INGRESOS!C11 -> 19000000 | D7: =INGRESOS!D11 -> 19950000 | E7: =INGRESOS!E11 -> 20947500 | F7: =INGRESOS!F11 -> 21994875 | G7: =INGRESOS!G11 -> 23094619
B8: COSTOS DE PRODUCCION | C8: ='COSTOS TOTALES'!C23 -> 8764900 | D8: ='COSTOS TOTALES'!D23 -> 9203145 | E8: ='COSTOS TOTALES'!E23 -> 9663302.2 | F8: ='COSTOS TOTALES'!F23 -> 10146467 | G8: ='COSTOS TOTALES'!G23 -> 10653791
B10: UTILIDAD BRUTA | C10: =C7-C8 -> 10235100 | D10: =D7-D8 -> 10746855 | E10: =E7-E8 -> 11284198 | F10: =F7-F8 -> 11848408 | G10: =G7-G8 -> 12440828
B12: GASTOS DE ADMINISTRACION Y VENTAS | C12: ='COSTOS TOTALES'!C14 -> 1128000 | D12: ='COSTOS TOTALES'!D14 -> 1184400 | E12: ='COSTOS TOTALES'!E14 -> 1243620 | F12: ='COSTOS TOTALES'!F14 -> 1305801 | G12: ='COSTOS TOTALES'!G14 -> 1371091.1
B15: UTILIDAD DE OPERACIÓN | C15: =C10-C12-C13 -> 9107100 | D15: =D10-D12-D13 -> 9562455 | E15: =E10-E12-E13 -> 10040578 | F15: =F10-F12-F13 -> 10542607 | G15: =G10-G12-G13 -> 11069737
B17: Reintegros | C17: 0 | D17: 0 | E17: 0 | F17: 0 | G17: 0
B18: Intereses | C18: 0 | D18: 0 | E18: 0 | F18: 0 | G18: 0
B21: UTILIDADES ANTES DE IMPUESTOS | C21: =C15-C18-C19-C17-C20 -> 9107100 | D21: =D15-D18-D19-D17-D20 -> 9562455 | E21: =E15-E18-E19-E17-E20 -> 10040578 | F21: =F15-F18-F19-F17-F20 -> 10542607 | G21: =G15-G18-G19-G17-G20 -> 11069737
B26: UTILIDAD NETA | C26: =C21-C23-C24 -> 9107100 | D26: =D21-D23-D24 -> 9562455 | E26: =E21-E23-E24 -> 10040578 | F26: =F21-F23-F24 -> 10542607 | G26: =G21-G23-G24 -> 11069737
B29: Egresos Totales | C29: =C8+C12+C17+C18+C19+C23+C24 -> 9892900 | D29: =D8+D12+D17+D18+D19+D23+D24 -> 10387545 | E29: =E8+E12+E17+E18+E19+E23+E24 -> 10906922 | F29: =F8+F12+F17+F18+F19+F23+F24 -> 11452268 | G29: =G8+G12+G17+G18+G19+G23+G24 -> 12024882
B30: incluyendo impuestos, reintegros, pago de intereses

Sheet RENTABILIDAD
D2: EVALUACION FINANCIERA
B4: INDICADORES FINANCIEROS
B5: FLUJO NETO DE EFECTIVO
D6: Inversiones para el proyecto | H6: Valor de Rescate | J6: Flujo Neto de Efectivo
B7: Año de | C7: Ingresos | D7: Egresos | E7: Fija | F7: Diferida | G7: Cap de trab. | H7: Valor | I7: Recup. De
B8: operación | C8: totales* | D8: totales | H8: Residual | I8: cap. De Trab.
B9: 0 | C9: 0 | D9: 0 | E9: =INVERSIONES!F14 -> 25200000 | F9: =INVERSIONES!F18 -> 0 | G9: =INVERSIONES!F23 -> 7714900 | J9: =C9-D9-E9-F9-G9+H9+I9 -> -32914900
B10: 1 | C10: ='ESTADO RESULTADOS'!C7 -> 19000000 | D10: ='ESTADO RESULTADOS'!C29 -> 9892900 | J10: =C10-D10-E10-F10-G10+H10+I10 -> 9107100
B11: 2 | C11: ='ESTADO RESULTADOS'!D7 -> 19950000 | D11: ='ESTADO RESULTADOS'!D29 -> 10387545 | J11: =C11-D11-E11-F11-G11+H11+I11 -> 9562455
B12: 3 | C12: ='ESTADO RESULTADOS'!E7 -> 20947500 | D12: ='ESTADO RESULTADOS'!E29 -> 10906922 | J12: =C12-D12-E12-F12-G12+H12+I12 -> 10040578
B13: 4 | C13: ='ESTADO RESULTADOS'!F7 -> 21994875 | D13: ='ESTADO RESULTADOS'!F29 -> 11452268 | J13: =C13-D13-E13-F13-G13+H13+I13 -> 10542607
B14: 5 | C14: ='ESTADO RESULTADOS'!G7 -> 23094619 | D14: ='ESTADO RESULTADOS'!G29 -> 12024882 | H14: =DEPREC!J15 -> 11485714 | J14: =C14-D14-E14-F14-G14+H14+I14 -> 22555451
B16: CALCULO DEL VAN, R B/C Y TIR CON UNA TASA DE DESCUENTO DEL 10%
B17: Año | C17: Costos | D17: Beneficios | E17: Factor de | F17: Costos | G17: Beneficios | H17: Flujo neto de
B18: de | C18: totales | D18: totales | E18: actualización | F18: actualizados | G18: actualizados | H18: efectivo act.
B19: operación | C19: ($) | D19: ($) | E19: 0.1 | F19: ($) | G19: ($) | H19: ($)
B20: 0 | C20: =SUM(D9,E9,F9,G9) -> 32914900 | D20: =C9+H9+I9 -> 0 | E20: =1/(1+E19)^B20 -> 1 | F20: =+E20*C20 -> 32914900 | G20: =+E20*D20 -> 0 | H20: =+G20-F20 -> -32914900
B21: 1 | C21: =SUM(D10,E10,F10,G10) -> 9892900 | D21: =C10+H10+I10 -> 19000000 | E21: =1/(1+E19)^B21 -> 0.90909091 | F21: =+E21*C21 -> 8993545.5 | G21: =+E21*D21 -> 17272727 | H21: =+G21-F21 -> 8279181.8
B22: 2 | C22: =SUM(D11,E11,F11,G11) -> 10387545 | D22: =C11+H11+I11 -> 19950000 | E22: =1/(1+E19)^B22 -> 0.82644628 | F22: =+E22*C22 -> 8584747.9 | G22: =+E22*D22 -> 16487603 | H22: =+G22-F22 -> 7902855.4
B23: 3 | C23: =SUM(D12,E12,F12,G12) -> 10906922 | D23: =C12+H12+I12 -> 20947500 | E23: =1/(1+E19)^B23 -> 0.7513148 | F23: =+E23*C23 -> 8194532.1 | G23: =+E23*D23 -> 15738167 | H23: =+G23-F23 -> 7543634.7
B24: 4 | C24: =SUM(D13,E13,F13,G13) -> 11452268 | D24: =C13+H13+I13 -> 21994875 | E24: =1/(1+E19)^B24 -> 0.68301346 | F24: =+E24*C24 -> 7822053.4 | G24: =+E24*D24 -> 15022796 | H24: =+G24-F24 -> 7200742.2
B25: 5 | C25: =SUM(D14,E14,F14,G14) -> 12024882 | D25: =C14+H14+I14 -> 34580333 | E25: =1/(1+E19)^B25 -> 0.62092132 | F25: =+E25*C25 -> 7466505.5 | G25: =+E25*D25 -> 21471666 | H25: =+G25-F25 -> 14005161
B26: Total | C26: =SUM(C20:C24) -> 75554536 | D26: =SUM(D20:D25) -> 1.1647271e+08 | F26: =SUM(F20:F25) -> 73976284 | G26: =SUM(G20:G25) -> 85992959 | H26: =SUM(H20:H25) -> 12016675
C28: Los indicadores financieros que arroja el proyecto son:
D29: VAN= | E29: =H26 -> 12016675 | F29: =IF(E29>0,"Viable","Se rechaza") -> Viable
D30: TIR = | E30: {=IRR((D20:D25)-(C20:C25))} -> 0.21515486 | F30: =IF(E30>E19,"Viable","Se rechaza") -> Viable
D31: B/C = | E31: =G26/F26 -> 1.1624396 | F31: =IF(E31>=1,"Viable","Se rechaza") -> Viable

Sheet PUNTO EQUILIBRIO
B1: ='ESTADO RESULTADOS'!B1 -> Modelo agrosostenible para la producción agrícola con el fin de promover la adaptación ante el cambio climático en el departamento de Bolívar. Cultivo de Yuca y Frijol Caupí
B2: PUNTO DE EQUILIBRIO
B4: CONCEPTOS / AÑO | C4: AÑO 1 | D4: AÑO 2 | E4: AÑO 3 | F4: AÑO 4 | G4: AÑO 5
B5: VENTAS | C5: =INGRESOS!C11 -> 19000000 | D5: =INGRESOS!D11 -> 19950000 | E5: =INGRESOS!E11 -> 20947500 | F5: =INGRESOS!F11 -> 21994875 | G5: =INGRESOS!G11 -> 23094619
B6: COSTOS FIJOS | C6: ='COSTOS TOTALES'!C26 -> 1128000 | D6: ='COSTOS TOTALES'!D26 -> 1184400 | E6: ='COSTOS TOTALES'!E26 -> 1243620 | F6: ='COSTOS TOTALES'!F26 -> 1305801 | G6: ='COSTOS TOTALES'!G26 -> 1371091.1
B7: COSTOS VARIABLES | C7: ='COSTOS TOTALES'!C27 -> 8764900 | D7: ='COSTOS TOTALES'!D27 -> 9203145 | E7: ='COSTOS TOTALES'!E27 -> 9663302.2 | F7: ='COSTOS TOTALES'!F27 -> 10146467 | G7: ='COSTOS TOTALES'!G27 -> 10653791
B8: COSTOS TOTALES | C8: =SUM(C6:C7) -> 9892900 | D8: =SUM(D6:D7) -> 10387545 | E8: =SUM(E6:E7) -> 10906922 | F8: =SUM(F6:F7) -> 11452268 | G8: =SUM(G6:G7) -> 12024882
B9: PUNTO DE EQUILIBRIO $ | C9: =(C6/(1-C7/C5)) -> 2093970.7 | D9: =(D6/(1-D7/D5)) -> 2198669.3 | E9: =(E6/(1-E7/E5)) -> 2308602.7 | F9: =(F6/(1-F7/F5)) -> 2424032.9 | G9: =(G6/(1-G7/G5)) -> 2545234.5
B10: PUNTO DE EQUILIBRIO % | C10: =C9/C5 -> 0.11020899 | D10: =D9/D5 -> 0.11020899 | E10: =E9/E5 -> 0.11020899 | F10: =F9/F5 -> 0.11020899 | G10: =G9/G5 -> 0.11020899

Sheet REC
B2: PERÍODO DE RECUPERACIÓN DE LA INVERSION
C4: 0 | D4: 1 | E4: 2 | F4: 3 | G4: 4 | H4: 5
B5: FLUJO ACT. | C5: =RENTABILIDAD!H20 -> -32914900 | D5: =RENTABILIDAD!H21 -> 8279181.8 | E5: =RENTABILIDAD!H22 -> 7902855.4 | F5: =RENTABILIDAD!H23 -> 7543634.7 | G5: =RENTABILIDAD!H24 -> 7200742.2 | H5: =RENTABILIDAD!H25 -> 14005161
B6: SALDO | C6: =+C5 -> -32914900 | D6: =+D5+C6 -> -24635718 | E6: =+E5+D6 -> -16732863 | F6: =+F5+E6 -> -9189228.1 | G6: =+G5+F6 -> -1988485.9 | H6: =+H5+G6 -> 12016675
E9: El ultimo saldo negativo corresponde
E10: al numero de años de recuperacion
E13: Periodo de recuperacion
E14: 2 | F14: años

Sheet CAPITAL TRABAJO
B3: CALCULO DE CAPITAL DE TRABAJO
B4: CONCEPTO | C4: MESES PRIMER AÑO
C5: Ene | D5: Feb | E5: Mar | F5: Abr | G5: May | H5: Jun | I5: Jul | J5: Ago | K5: Sep | L5: Oct | M5: Nov | N5: Dic | O5: TOTAL
B6: INGRESOS
B7: Por Ventas | D7: =INGRESOS!C11/11 -> 1727272.7 | E7: =D7 -> 1727272.7 | F7: =E7 -> 1727272.7 | G7: =F7 -> 1727272.7 | H7: =G7 -> 1727272.7 | I7: =H7 -> 1727272.7 | J7: =I7 -> 1727272.7 | K7: =J7 -> 1727272.7 | L7: =K7 -> 1727272.7 | ... N7: =M7 -> 1727272.7 | O7: =SUM(C7:N7) -> 19000000
B8: EGRESOS
B9: Costos Variables | C9: ='MEMORIA COSTOS'!C22 -> 0 | D9: ='MEMORIA COSTOS'!D22 -> 0 | E9: ='MEMORIA COSTOS'!E22 -> 0 | F9: ='MEMORIA COSTOS'!F22 -> 0 | G9: ='MEMORIA COSTOS'!G22 -> 1050000 | H9: ='MEMORIA COSTOS'!H22 -> 0 | I9: ='MEMORIA COSTOS'!I22 -> 0 | J9: ='MEMORIA COSTOS'!J22 -> 0 | ... N9: ='MEMORIA COSTOS'!N22 -> 0 | O9: =SUM(C9:N9) -> 1050000
B10: Costos Fijos | C10: ='MEMORIA COSTOS'!C16 -> 0 | D10: ='MEMORIA COSTOS'!D16 -> 0 | E10: ='MEMORIA COSTOS'!E16 -> 0 | F10: ='MEMORIA COSTOS'!F16 -> 0 | G10: ='MEMORIA COSTOS'!G16 -> 1128000 | H10: ='MEMORIA COSTOS'!H16 -> 0 | I10: ='MEMORIA COSTOS'!I16 -> 0 | J10: ='MEMORIA COSTOS'!J16 -> 0 | ... N10: ='MEMORIA COSTOS'!N16 -> 0 | O10: =SUM(C10:N10) -> 1128000
B12: Total Egresos | C12: =SUM(C9:C11) -> 0 | D12: =SUM(D9:D11) -> 0 | E12: =SUM(E9:E11) -> 0 | F12: =SUM(F9:F11) -> 0 | G12: =SUM(G9:G11) -> 2178000 | H12: =SUM(H9:H11) -> 0 | I12: =SUM(I9:I11) -> 0 | J12: =SUM(J9:J11) -> 0 | ... N12: =SUM(N9:N11) -> 0 | O12: =SUM(C12:N12) -> 2178000
B14: Flujo de
B15: Efectivo | C15: =C7-C12 -> 0 | D15: =D7-D12 -> 1727272.7 | E15: =E7-E12 -> 1727272.7 | F15: =F7-F12 -> 1727272.7 | G15: =G7-G12 -> -450727.27 | H15: =H7-H12 -> 1727272.7 | I15: =I7-I12 -> 1727272.7 | J15: =J7-J12 -> 1727272.7 | ... O15: =O7-O12 -> 16822000
B16: Efectivo Acumulado | C16: =C15 -> 0 | D16: =D15+C16 -> 1727272.7 | E16: =E15+D16 -> 3454545.5 | F16: =F15+E16 -> 5181818.2 | G16: =G15+F16 -> 4731090.9 | H16: =H15+G16 -> 6458363.6 | I16: =I15+H16 -> 8185636.4 | J16: =J15+I16 -> 9912909.1 | K16: =K15+J16 -> 11640182 | ... N16: =N15+M16 -> 16822000

Sheet DEPREC
B2: CALCULO DE DEPRECIACIONES Y AMORTIZACIONES
B4: CONCEPTO | C4: UNIDAD | D4: CANTIDAD | E4: COSTO UNITARIO | F4: COSTO TOTAL | G4: Años de Vida Util | H4: Depreciacion Anual | I4: Drepreciacion en el periodo (5 Años) | J4: Valor Residual
B6: =INVERSIONES!B5 -> Sistema de riego por goteo fotovoltaico | C6: =INVERSIONES!C5 -> Obra | D6: =INVERSIONES!D5 -> 1 | E6: =INVERSIONES!E5 -> 15000000 | F6: =E6*D6 -> 15000000 | G6: 10 | H6: =F6/G6 -> 1500000 | I6: =H6*5 -> 7500000 | J6: =F6-I6 -> 7500000
B7: =INVERSIONES!B6 -> Electrobomba/motobomba electrica, Potencia: 3 Hp, Voltaje: 110 V | C7: =INVERSIONES!C6 -> equipo | D7: =INVERSIONES!D6 -> 1 | E7: =INVERSIONES!E6 -> 5000000 | F7: =E7*D7 -> 5000000 | G7: 10 | H7: =F7/G7 -> 500000 | I7: =H7*5 -> 2500000 | J7: =F7-I7 -> 2500000
B8: =INVERSIONES!B7 -> Sensor | C8: =INVERSIONES!C7 -> equipo | D8: =INVERSIONES!D7 -> 1 | E8: =INVERSIONES!E7 -> 5200000 | F8: =E8*D8 -> 5200000 | G8: 7 | H8: =F8/G8 -> 742857.14 | I8: =H8*5 -> 3714285.7 | J8: =F8-I8 -> 1485714.3
B15: TOTAL | F15: =SUM(F6:F14) -> 25200000 | H15: =SUM(H6:H14) -> 2742857.1 | I15: =SUM(I6:I14) -> 13714286 | J15: =SUM(J6:J14) -> 11485714
